Workbook

Sheet Sheet1
B2: Daun Choi
B3: Questions: On Moodle (Content related/ Organizational related)
B4: For personal issues only: daun.choi@tum.de

Sheet Task
B2: Forecasting | D2: YEAR | E2: MONTH | F2: ACTUAL DEMAND
A3: 1 | B3: A company produces a product, whose demand is observed for 3 consecutive years from 2023 to 2025, and has been recorded. Apply the following methods for making forecasts. You may use all past data to adjust the parameters (alpha in exponential smoothing, intercept and slope in regression) - Naïve - Naïve with trend - Naïve with seasonality - Moving average - Exponential smoothing - Linear Regression Compare the MAD and MSE for the above forecasting methods, and choose the most suitable one for the given dataset. | D3: 2023 | E3: JANUARY | F3: 19
E4: FEBRUARY | F4: 24
E5: MARCH | F5: 30
E6: APRIL | F6: 32
E7: MAY | F7: 29
E8: JUNE | F8: 33 | M8: Period | N8: Actual | O8: Forecast | P8: Actual-Forecast | Q8: Absolute error | R8: Error square
E9: JULY | F9: 34 | M9: 1 | N9: 5 | O9: 1 | P9: 4 | Q9: 4 | R9: 16
E10: AUGUST | F10: 29 | M10: 2 | N10: 6 | O10: 5 | P10: 1 | Q10: 1 | R10: 1
E11: SEPTEMBER | F11: 29 | M11: 3 | N11: 2 | O11: 3 | P11: -1 | Q11: 1 | R11: 1
E12: OCTOBER | F12: 32 | Q12: =AVERAGE(Q9:Q11) -> 2 | R12: =AVERAGE(R9:R11) -> 6
E13: NOVEMBER | F13: 31
E14: DECEMBER | F14: 25
D15: 2024 | E15: JANUARY | F15: 25
A16: 2 | B16: Apply the most suitable forecasting method you have selected to predict demand for 2026 and 2027. Calculate the control limits for 95% confidence level based on past data from 2023 to 2025. Find and plot errors for all 5 years and check if they fall within the control limits. Interpret your graphic result, and explain your findings. | E16: FEBRUARY | F16: 25
E17: MARCH | F17: 28
E18: APRIL | F18: 30
E19: MAY | F19: 30
E20: JUNE | F20: 32
E21: JULY | F21: 39
E22: AUGUST | F22: 38
E23: SEPTEMBER | F23: 37
E24: OCTOBER | F24: 40
E25: NOVEMBER | F25: 40
E26: DECEMBER | F26: 33
D27: 2025 | E27: JANUARY | F27: 35
E28: FEBRUARY | F28: 31
E29: MARCH | F29: 33
E30: APRIL | F30: 40
E31: MAY | F31: 38
E32: JUNE | F32: 36
E33: JULY | F33: 35
E34: AUGUST | F34: 29
E35: SEPTEMBER | F35: 25
E36: OCTOBER | F36: 30
E37: NOVEMBER | F37: 33
E38: DECEMBER | F38: 40

Sheet Naïve
B2: Naïve Forecast: Tomorrow will be the same as today
B4: YEAR | C4: MONTH | D4: ACTUAL DEMAND | E4: NAÏVE
E5: FORECAST | F5: ERROR | G5: ABSOLUTE ERROR | H5: ERROR2
B6: 2023 | C6: JANUARY | D6: 19
C7: FEBRUARY | D7: 24 | E7: =D6 -> 19 | F7: =D7-E7 -> 5 | G7: =ABS(F7) -> 5 | H7: =G7^2 -> 25
C8: MARCH | D8: 30 | E8: =D7 -> 24 | F8: =D8-E8 -> 6 | G8: =ABS(F8) -> 6 | H8: =G8^2 -> 36
C9: APRIL | D9: 32 | E9: =D8 -> 30 | F9: =D9-E9 -> 2 | G9: =ABS(F9) -> 2 | H9: =G9^2 -> 4
C10: MAY | D10: 29 | E10: =D9 -> 32 | F10: =D10-E10 -> -3 | G10: =ABS(F10) -> 3 | H10: =G10^2 -> 9
C11: JUNE | D11: 33 | E11: =D10 -> 29 | F11: =D11-E11 -> 4 | G11: =ABS(F11) -> 4 | H11: =G11^2 -> 16
C12: JULY | D12: 34 | E12: =D11 -> 33 | F12: =D12-E12 -> 1 | G12: =ABS(F12) -> 1 | H12: =G12^2 -> 1
C13: AUGUST | D13: 29 | E13: =D12 -> 34 | F13: =D13-E13 -> -5 | G13: =ABS(F13) -> 5 | H13: =G13^2 -> 25
C14: SEPTEMBER | D14: 29 | E14: =D13 -> 29 | F14: =D14-E14 -> 0 | G14: =ABS(F14) -> 0 | H14: =G14^2 -> 0
C15: OCTOBER | D15: 32 | E15: =D14 -> 29 | F15: =D15-E15 -> 3 | G15: =ABS(F15) -> 3 | H15: =G15^2 -> 9
C16: NOVEMBER | D16: 31 | E16: =D15 -> 32 | F16: =D16-E16 -> -1 | G16: =ABS(F16) -> 1 | H16: =G16^2 -> 1
C17: DECEMBER | D17: 25 | E17: =D16 -> 31 | F17: =D17-E17 -> -6 | G17: =ABS(F17) -> 6 | H17: =G17^2 -> 36
B18: 2024 | C18: JANUARY | D18: 25 | E18: =D17 -> 25 | F18: =D18-E18 -> 0 | G18: =ABS(F18) -> 0 | H18: =G18^2 -> 0
C19: FEBRUARY | D19: 25 | E19: =D18 -> 25 | F19: =D19-E19 -> 0 | G19: =ABS(F19) -> 0 | H19: =G19^2 -> 0
C20: MARCH | D20: 28 | E20: =D19 -> 25 | F20: =D20-E20 -> 3 | G20: =ABS(F20) -> 3 | H20: =G20^2 -> 9
C21: APRIL | D21: 30 | E21: =D20 -> 28 | F21: =D21-E21 -> 2 | G21: =ABS(F21) -> 2 | H21: =G21^2 -> 4
C22: MAY | D22: 30 | E22: =D21 -> 30 | F22: =D22-E22 -> 0 | G22: =ABS(F22) -> 0 | H22: =G22^2 -> 0
C23: JUNE | D23: 32 | E23: =D22 -> 30 | F23: =D23-E23 -> 2 | G23: =ABS(F23) -> 2 | H23: =G23^2 -> 4
C24: JULY | D24: 39 | E24: =D23 -> 32 | F24: =D24-E24 -> 7 | G24: =ABS(F24) -> 7 | H24: =G24^2 -> 49
C25: AUGUST | D25: 38 | E25: =D24 -> 39 | F25: =D25-E25 -> -1 | G25: =ABS(F25) -> 1 | H25: =G25^2 -> 1
C26: SEPTEMBER | D26: 37 | E26: =D25 -> 38 | F26: =D26-E26 -> -1 | G26: =ABS(F26) -> 1 | H26: =G26^2 -> 1
C27: OCTOBER | D27: 40 | E27: =D26 -> 37 | F27: =D27-E27 -> 3 | G27: =ABS(F27) -> 3 | H27: =G27^2 -> 9
C28: NOVEMBER | D28: 40 | E28: =D27 -> 40 | F28: =D28-E28 -> 0 | G28: =ABS(F28) -> 0 | H28: =G28^2 -> 0
C29: DECEMBER | D29: 33 | E29: =D28 -> 40 | F29: =D29-E29 -> -7 | G29: =ABS(F29) -> 7 | H29: =G29^2 -> 49
B30: 2025 | C30: JANUARY | D30: 35 | E30: =D29 -> 33 | F30: =D30-E30 -> 2 | G30: =ABS(F30) -> 2 | H30: =G30^2 -> 4
C31: FEBRUARY | D31: 31 | E31: =D30 -> 35 | F31: =D31-E31 -> -4 | G31: =ABS(F31) -> 4 | H31: =G31^2 -> 16
C32: MARCH | D32: 33 | E32: =D31 -> 31 | F32: =D32-E32 -> 2 | G32: =ABS(F32) -> 2 | H32: =G32^2 -> 4
C33: APRIL | D33: 40 | E33: =D32 -> 33 | F33: =D33-E33 -> 7 | G33: =ABS(F33) -> 7 | H33: =G33^2 -> 49
C34: MAY | D34: 38 | E34: =D33 -> 40 | F34: =D34-E34 -> -2 | G34: =ABS(F34) -> 2 | H34: =G34^2 -> 4
C35: JUNE | D35: 36 | E35: =D34 -> 38 | F35: =D35-E35 -> -2 | G35: =ABS(F35) -> 2 | H35: =G35^2 -> 4
C36: JULY | D36: 35 | E36: =D35 -> 36 | F36: =D36-E36 -> -1 | G36: =ABS(F36) -> 1 | H36: =G36^2 -> 1
C37: AUGUST | D37: 29 | E37: =D36 -> 35 | F37: =D37-E37 -> -6 | G37: =ABS(F37) -> 6 | H37: =G37^2 -> 36
C38: SEPTEMBER | D38: 25 | E38: =D37 -> 29 | F38: =D38-E38 -> -4 | G38: =ABS(F38) -> 4 | H38: =G38^2 -> 16
C39: OCTOBER | D39: 30 | E39: =D38 -> 25 | F39: =D39-E39 -> 5 | G39: =ABS(F39) -> 5 | H39: =G39^2 -> 25
C40: NOVEMBER | D40: 33 | E40: =D39 -> 30 | F40: =D40-E40 -> 3 | G40: =ABS(F40) -> 3 | H40: =G40^2 -> 9
C41: DECEMBER | D41: 40 | E41: =D40 -> 33 | F41: =D41-E41 -> 7 | G41: =ABS(F41) -> 7 | H41: =G41^2 -> 49
G42: =AVERAGE(G7:G41) -> 3.0571429 | H42: =AVERAGE(H7:H41) -> 14.428571
...

Sheet Naïve with Trend
B2: Naïve Forecast with Trend: Same trend from last period
B4: YEAR | C4: MONTH | D4: ACTUAL DEMAND | E4: NAÏVE WITH TREND
E5: FORECAST | F5: ERROR | G5: ABSOLUTE ERROR | H5: ERROR2
B6: 2023 | C6: JANUARY | D6: 19
C7: FEBRUARY | D7: 24
C8: MARCH | D8: 30 | E8: =D7+(D7-D6) -> 29 | F8: =D8-E8 -> 1 | G8: =ABS(F8) -> 1 | H8: =G8^2 -> 1
C9: APRIL | D9: 32 | E9: =D8+(D8-D7) -> 36 | F9: =D9-E9 -> -4 | G9: =ABS(F9) -> 4 | H9: =G9^2 -> 16
C10: MAY | D10: 29 | E10: =D9+(D9-D8) -> 34 | F10: =D10-E10 -> -5 | G10: =ABS(F10) -> 5 | H10: =G10^2 -> 25
C11: JUNE | D11: 33 | E11: =D10+(D10-D9) -> 26 | F11: =D11-E11 -> 7 | G11: =ABS(F11) -> 7 | H11: =G11^2 -> 49
C12: JULY | D12: 34 | E12: =D11+(D11-D10) -> 37 | F12: =D12-E12 -> -3 | G12: =ABS(F12) -> 3 | H12: =G12^2 -> 9
C13: AUGUST | D13: 29 | E13: =D12+(D12-D11) -> 35 | F13: =D13-E13 -> -6 | G13: =ABS(F13) -> 6 | H13: =G13^2 -> 36
C14: SEPTEMBER | D14: 29 | E14: =D13+(D13-D12) -> 24 | F14: =D14-E14 -> 5 | G14: =ABS(F14) -> 5 | H14: =G14^2 -> 25
C15: OCTOBER | D15: 32 | E15: =D14+(D14-D13) -> 29 | F15: =D15-E15 -> 3 | G15: =ABS(F15) -> 3 | H15: =G15^2 -> 9
C16: NOVEMBER | D16: 31 | E16: =D15+(D15-D14) -> 35 | F16: =D16-E16 -> -4 | G16: =ABS(F16) -> 4 | H16: =G16^2 -> 16
C17: DECEMBER | D17: 25 | E17: =D16+(D16-D15) -> 30 | F17: =D17-E17 -> -5 | G17: =ABS(F17) -> 5 | H17: =G17^2 -> 25
B18: 2024 | C18: JANUARY | D18: 25 | E18: =D17+(D17-D16) -> 19 | F18: =D18-E18 -> 6 | G18: =ABS(F18) -> 6 | H18: =G18^2 -> 36
C19: FEBRUARY | D19: 25 | E19: =D18+(D18-D17) -> 25 | F19: =D19-E19 -> 0 | G19: =ABS(F19) -> 0 | H19: =G19^2 -> 0
C20: MARCH | D20: 28 | E20: =D19+(D19-D18) -> 25 | F20: =D20-E20 -> 3 | G20: =ABS(F20) -> 3 | H20: =G20^2 -> 9
C21: APRIL | D21: 30 | E21: =D20+(D20-D19) -> 31 | F21: =D21-E21 -> -1 | G21: =ABS(F21) -> 1 | H21: =G21^2 -> 1
C22: MAY | D22: 30 | E22: =D21+(D21-D20) -> 32 | F22: =D22-E22 -> -2 | G22: =ABS(F22) -> 2 | H22: =G22^2 -> 4
C23: JUNE | D23: 32 | E23: =D22+(D22-D21) -> 30 | F23: =D23-E23 -> 2 | G23: =ABS(F23) -> 2 | H23: =G23^2 -> 4
C24: JULY | D24: 39 | E24: =D23+(D23-D22) -> 34 | F24: =D24-E24 -> 5 | G24: =ABS(F24) -> 5 | H24: =G24^2 -> 25
C25: AUGUST | D25: 38 | E25: =D24+(D24-D23) -> 46 | F25: =D25-E25 -> -8 | G25: =ABS(F25) -> 8 | H25: =G25^2 -> 64
C26: SEPTEMBER | D26: 37 | E26: =D25+(D25-D24) -> 37 | F26: =D26-E26 -> 0 | G26: =ABS(F26) -> 0 | H26: =G26^2 -> 0
C27: OCTOBER | D27: 40 | E27: =D26+(D26-D25) -> 36 | F27: =D27-E27 -> 4 | G27: =ABS(F27) -> 4 | H27: =G27^2 -> 16
C28: NOVEMBER | D28: 40 | E28: =D27+(D27-D26) -> 43 | F28: =D28-E28 -> -3 | G28: =ABS(F28) -> 3 | H28: =G28^2 -> 9
C29: DECEMBER | D29: 33 | E29: =D28+(D28-D27) -> 40 | F29: =D29-E29 -> -7 | G29: =ABS(F29) -> 7 | H29: =G29^2 -> 49
B30: 2025 | C30: JANUARY | D30: 35 | E30: =D29+(D29-D28) -> 26 | F30: =D30-E30 -> 9 | G30: =ABS(F30) -> 9 | H30: =G30^2 -> 81
C31: FEBRUARY | D31: 31 | E31: =D30+(D30-D29) -> 37 | F31: =D31-E31 -> -6 | G31: =ABS(F31) -> 6 | H31: =G31^2 -> 36
C32: MARCH | D32: 33 | E32: =D31+(D31-D30) -> 27 | F32: =D32-E32 -> 6 | G32: =ABS(F32) -> 6 | H32: =G32^2 -> 36
C33: APRIL | D33: 40 | E33: =D32+(D32-D31) -> 35 | F33: =D33-E33 -> 5 | G33: =ABS(F33) -> 5 | H33: =G33^2 -> 25
C34: MAY | D34: 38 | E34: =D33+(D33-D32) -> 47 | F34: =D34-E34 -> -9 | G34: =ABS(F34) -> 9 | H34: =G34^2 -> 81
C35: JUNE | D35: 36 | E35: =D34+(D34-D33) -> 36 | F35: =D35-E35 -> 0 | G35: =ABS(F35) -> 0 | H35: =G35^2 -> 0
C36: JULY | D36: 35 | E36: =D35+(D35-D34) -> 34 | F36: =D36-E36 -> 1 | G36: =ABS(F36) -> 1 | H36: =G36^2 -> 1
C37: AUGUST | D37: 29 | E37: =D36+(D36-D35) -> 34 | F37: =D37-E37 -> -5 | G37: =ABS(F37) -> 5 | H37: =G37^2 -> 25
C38: SEPTEMBER | D38: 25 | E38: =D37+(D37-D36) -> 23 | F38: =D38-E38 -> 2 | G38: =ABS(F38) -> 2 | H38: =G38^2 -> 4
C39: OCTOBER | D39: 30 | E39: =D38+(D38-D37) -> 21 | F39: =D39-E39 -> 9 | G39: =ABS(F39) -> 9 | H39: =G39^2 -> 81
C40: NOVEMBER | D40: 33 | E40: =D39+(D39-D38) -> 35 | F40: =D40-E40 -> -2 | G40: =ABS(F40) -> 2 | H40: =G40^2 -> 4
C41: DECEMBER | D41: 40 | E41: =D40+(D40-D39) -> 36 | F41: =D41-E41 -> 4 | G41: =ABS(F41) -> 4 | H41: =G41^2 -> 16
G42: =AVERAGE(G8:G41) -> 4.1764706 | H42: =AVERAGE(H8:H41) -> 24.058824
...

Sheet Naïve with Seasonality
B2: Naïve Forecast with Seasonality: Same as last same season
B3: Consider 1 year as one season.
B4: YEAR | C4: MONTH | D4: ACTUAL DEMAND | E4: NAÏVE WITH SEASONALITY
E5: FORECAST | F5: ERROR | G5: ABSOLUTE ERROR | H5: ERROR2
B6: 2023 | C6: JANUARY | D6: 19
C7: FEBRUARY | D7: 24
C8: MARCH | D8: 30
C9: APRIL | D9: 32
C10: MAY | D10: 29
C11: JUNE | D11: 33
C12: JULY | D12: 34
C13: AUGUST | D13: 29
C14: SEPTEMBER | D14: 29
C15: OCTOBER | D15: 32
C16: NOVEMBER | D16: 31
C17: DECEMBER | D17: 25
B18: 2024 | C18: JANUARY | D18: 25 | E18: =D6 -> 19 | F18: =D18-E18 -> 6 | G18: =ABS(F18) -> 6 | H18: =G18^2 -> 36
C19: FEBRUARY | D19: 25 | E19: =D7 -> 24 | F19: =D19-E19 -> 1 | G19: =ABS(F19) -> 1 | H19: =G19^2 -> 1
C20: MARCH | D20: 28 | E20: =D8 -> 30 | F20: =D20-E20 -> -2 | G20: =ABS(F20) -> 2 | H20: =G20^2 -> 4
C21: APRIL | D21: 30 | E21: =D9 -> 32 | F21: =D21-E21 -> -2 | G21: =ABS(F21) -> 2 | H21: =G21^2 -> 4
C22: MAY | D22: 30 | E22: =D10 -> 29 | F22: =D22-E22 -> 1 | G22: =ABS(F22) -> 1 | H22: =G22^2 -> 1
C23: JUNE | D23: 32 | E23: =D11 -> 33 | F23: =D23-E23 -> -1 | G23: =ABS(F23) -> 1 | H23: =G23^2 -> 1
C24: JULY | D24: 39 | E24: =D12 -> 34 | F24: =D24-E24 -> 5 | G24: =ABS(F24) -> 5 | H24: =G24^2 -> 25
C25: AUGUST | D25: 38 | E25: =D13 -> 29 | F25: =D25-E25 -> 9 | G25: =ABS(F25) -> 9 | H25: =G25^2 -> 81
C26: SEPTEMBER | D26: 37 | E26: =D14 -> 29 | F26: =D26-E26 -> 8 | G26: =ABS(F26) -> 8 | H26: =G26^2 -> 64
C27: OCTOBER | D27: 40 | E27: =D15 -> 32 | F27: =D27-E27 -> 8 | G27: =ABS(F27) -> 8 | H27: =G27^2 -> 64
C28: NOVEMBER | D28: 40 | E28: =D16 -> 31 | F28: =D28-E28 -> 9 | G28: =ABS(F28) -> 9 | H28: =G28^2 -> 81
C29: DECEMBER | D29: 33 | E29: =D17 -> 25 | F29: =D29-E29 -> 8 | G29: =ABS(F29) -> 8 | H29: =G29^2 -> 64
B30: 2025 | C30: JANUARY | D30: 35 | E30: =D18 -> 25 | F30: =D30-E30 -> 10 | G30: =ABS(F30) -> 10 | H30: =G30^2 -> 100
C31: FEBRUARY | D31: 31 | E31: =D19 -> 25 | F31: =D31-E31 -> 6 | G31: =ABS(F31) -> 6 | H31: =G31^2 -> 36
C32: MARCH | D32: 33 | E32: =D20 -> 28 | F32: =D32-E32 -> 5 | G32: =ABS(F32) -> 5 | H32: =G32^2 -> 25
C33: APRIL | D33: 40 | E33: =D21 -> 30 | F33: =D33-E33 -> 10 | G33: =ABS(F33) -> 10 | H33: =G33^2 -> 100
C34: MAY | D34: 38 | E34: =D22 -> 30 | F34: =D34-E34 -> 8 | G34: =ABS(F34) -> 8 | H34: =G34^2 -> 64
C35: JUNE | D35: 36 | E35: =D23 -> 32 | F35: =D35-E35 -> 4 | G35: =ABS(F35) -> 4 | H35: =G35^2 -> 16
C36: JULY | D36: 35 | E36: =D24 -> 39 | F36: =D36-E36 -> -4 | G36: =ABS(F36) -> 4 | H36: =G36^2 -> 16
C37: AUGUST | D37: 29 | E37: =D25 -> 38 | F37: =D37-E37 -> -9 | G37: =ABS(F37) -> 9 | H37: =G37^2 -> 81
C38: SEPTEMBER | D38: 25 | E38: =D26 -> 37 | F38: =D38-E38 -> -12 | G38: =ABS(F38) -> 12 | H38: =G38^2 -> 144
C39: OCTOBER | D39: 30 | E39: =D27 -> 40 | F39: =D39-E39 -> -10 | G39: =ABS(F39) -> 10 | H39: =G39^2 -> 100
C40: NOVEMBER | D40: 33 | E40: =D28 -> 40 | F40: =D40-E40 -> -7 | G40: =ABS(F40) -> 7 | H40: =G40^2 -> 49
C41: DECEMBER | D41: 40 | E41: =D29 -> 33 | F41: =D41-E41 -> 7 | G41: =ABS(F41) -> 7 | H41: =G41^2 -> 49
...

Sheet Moving Average
B2: Moving Average: Same as last n periods
B3: Consider 1 quarter as one period.
B4: YEAR | C4: MONTH | D4: ACTUAL DEMAND | E4: MOVING AVERAGE
E5: FORECAST | F5: ERROR | G5: ABSOLUTE ERROR | H5: ERROR2
B6: 2023 | C6: JANUARY | D6: 19
C7: FEBRUARY | D7: 24
C8: MARCH | D8: 30
C9: APRIL | D9: 32 | E9: =AVERAGE(D6:D8) -> 24.333333 | F9: =D9-E9 -> 7.6666667 | G9: =ABS(F9) -> 7.6666667 | H9: =G9^2 -> 58.777778
C10: MAY | D10: 29 | E10: =AVERAGE(D7:D9) -> 28.666667 | F10: =D10-E10 -> 0.33333333 | G10: =ABS(F10) -> 0.33333333 | H10: =G10^2 -> 0.11111111
C11: JUNE | D11: 33 | E11: =AVERAGE(D8:D10) -> 30.333333 | F11: =D11-E11 -> 2.6666667 | G11: =ABS(F11) -> 2.6666667 | H11: =G11^2 -> 7.1111111
C12: JULY | D12: 34 | E12: =AVERAGE(D9:D11) -> 31.333333 | F12: =D12-E12 -> 2.6666667 | G12: =ABS(F12) -> 2.6666667 | H12: =G12^2 -> 7.1111111
C13: AUGUST | D13: 29 | E13: =AVERAGE(D10:D12) -> 32 | F13: =D13-E13 -> -3 | G13: =ABS(F13) -> 3 | H13: =G13^2 -> 9
C14: SEPTEMBER | D14: 29 | E14: =AVERAGE(D11:D13) -> 32 | F14: =D14-E14 -> -3 | G14: =ABS(F14) -> 3 | H14: =G14^2 -> 9
C15: OCTOBER | D15: 32 | E15: =AVERAGE(D12:D14) -> 30.666667 | F15: =D15-E15 -> 1.3333333 | G15: =ABS(F15) -> 1.3333333 | H15: =G15^2 -> 1.7777778
C16: NOVEMBER | D16: 31 | E16: =AVERAGE(D13:D15) -> 30 | F16: =D16-E16 -> 1 | G16: =ABS(F16) -> 1 | H16: =G16^2 -> 1
C17: DECEMBER | D17: 25 | E17: =AVERAGE(D14:D16) -> 30.666667 | F17: =D17-E17 -> -5.6666667 | G17: =ABS(F17) -> 5.6666667 | H17: =G17^2 -> 32.111111
B18: 2024 | C18: JANUARY | D18: 25 | E18: =AVERAGE(D15:D17) -> 29.333333 | F18: =D18-E18 -> -4.3333333 | G18: =ABS(F18) -> 4.3333333 | H18: =G18^2 -> 18.777778
C19: FEBRUARY | D19: 25 | E19: =AVERAGE(D16:D18) -> 27 | F19: =D19-E19 -> -2 | G19: =ABS(F19) -> 2 | H19: =G19^2 -> 4
C20: MARCH | D20: 28 | E20: =AVERAGE(D17:D19) -> 25 | F20: =D20-E20 -> 3 | G20: =ABS(F20) -> 3 | H20: =G20^2 -> 9
C21: APRIL | D21: 30 | E21: =AVERAGE(D18:D20) -> 26 | F21: =D21-E21 -> 4 | G21: =ABS(F21) -> 4 | H21: =G21^2 -> 16
C22: MAY | D22: 30 | E22: =AVERAGE(D19:D21) -> 27.666667 | F22: =D22-E22 -> 2.3333333 | G22: =ABS(F22) -> 2.3333333 | H22: =G22^2 -> 5.4444444
C23: JUNE | D23: 32 | E23: =AVERAGE(D20:D22) -> 29.333333 | F23: =D23-E23 -> 2.6666667 | G23: =ABS(F23) -> 2.6666667 | H23: =G23^2 -> 7.1111111
C24: JULY | D24: 39 | E24: =AVERAGE(D21:D23) -> 30.666667 | F24: =D24-E24 -> 8.3333333 | G24: =ABS(F24) -> 8.3333333 | H24: =G24^2 -> 69.444444
C25: AUGUST | D25: 38 | E25: =AVERAGE(D22:D24) -> 33.666667 | F25: =D25-E25 -> 4.3333333 | G25: =ABS(F25) -> 4.3333333 | H25: =G25^2 -> 18.777778
C26: SEPTEMBER | D26: 37 | E26: =AVERAGE(D23:D25) -> 36.333333 | F26: =D26-E26 -> 0.66666667 | G26: =ABS(F26) -> 0.66666667 | H26: =G26^2 -> 0.44444444
C27: OCTOBER | D27: 40 | E27: =AVERAGE(D24:D26) -> 38 | F27: =D27-E27 -> 2 | G27: =ABS(F27) -> 2 | H27: =G27^2 -> 4
C28: NOVEMBER | D28: 40 | E28: =AVERAGE(D25:D27) -> 38.333333 | F28: =D28-E28 -> 1.6666667 | G28: =ABS(F28) -> 1.6666667 | H28: =G28^2 -> 2.7777778
C29: DECEMBER | D29: 33 | E29: =AVERAGE(D26:D28) -> 39 | F29: =D29-E29 -> -6 | G29: =ABS(F29) -> 6 | H29: =G29^2 -> 36
B30: 2025 | C30: JANUARY | D30: 35 | E30: =AVERAGE(D27:D29) -> 37.666667 | F30: =D30-E30 -> -2.6666667 | G30: =ABS(F30) -> 2.6666667 | H30: =G30^2 -> 7.1111111
C31: FEBRUARY | D31: 31 | E31: =AVERAGE(D28:D30) -> 36 | F31: =D31-E31 -> -5 | G31: =ABS(F31) -> 5 | H31: =G31^2 -> 25
C32: MARCH | D32: 33 | E32: =AVERAGE(D29:D31) -> 33 | F32: =D32-E32 -> 0 | G32: =ABS(F32) -> 0 | H32: =G32^2 -> 0
C33: APRIL | D33: 40 | E33: =AVERAGE(D30:D32) -> 33 | F33: =D33-E33 -> 7 | G33: =ABS(F33) -> 7 | H33: =G33^2 -> 49
C34: MAY | D34: 38 | E34: =AVERAGE(D31:D33) -> 34.666667 | F34: =D34-E34 -> 3.3333333 | G34: =ABS(F34) -> 3.3333333 | H34: =G34^2 -> 11.111111
C35: JUNE | D35: 36 | E35: =AVERAGE(D32:D34) -> 37 | F35: =D35-E35 -> -1 | G35: =ABS(F35) -> 1 | H35: =G35^2 -> 1
C36: JULY | D36: 35 | E36: =AVERAGE(D33:D35) -> 38 | F36: =D36-E36 -> -3 | G36: =ABS(F36) -> 3 | H36: =G36^2 -> 9
C37: AUGUST | D37: 29 | E37: =AVERAGE(D34:D36) -> 36.333333 | F37: =D37-E37 -> -7.3333333 | G37: =ABS(F37) -> 7.3333333 | H37: =G37^2 -> 53.777778
C38: SEPTEMBER | D38: 25 | E38: =AVERAGE(D35:D37) -> 33.333333 | F38: =D38-E38 -> -8.3333333 | G38: =ABS(F38) -> 8.3333333 | H38: =G38^2 -> 69.444444
C39: OCTOBER | D39: 30 | E39: =AVERAGE(D36:D38) -> 29.666667 | F39: =D39-E39 -> 0.33333333 | G39: =ABS(F39) -> 0.33333333 | H39: =G39^2 -> 0.11111111
C40: NOVEMBER | D40: 33 | E40: =AVERAGE(D37:D39) -> 28 | F40: =D40-E40 -> 5 | G40: =ABS(F40) -> 5 | H40: =G40^2 -> 25
C41: DECEMBER | D41: 40 | E41: =AVERAGE(D38:D40) -> 29.333333 | F41: =D41-E41 -> 10.666667 | G41: =ABS(F41) -> 10.666667 | H41: =G41^2 -> 113.77778
...

Sheet Exponential Smoothing
B2: Exponential Smoothing: Exponentially weighted average of previous periods
B3: Consider initial forecast of 25 and smoothing constant of 0.5
B4: YEAR | C4: MONTH | D4: ACTUAL DEMAND | E4: EXPONENTIAL SMOOTHING
E5: FORECAST | F5: ERROR | G5: ABSOLUTE ERROR | H5: ERROR2
B6: 2023 | C6: JANUARY | D6: 19 | E6: 25 | F6: =D6-E6 -> -6 | G6: =ABS(F6) -> 6 | H6: =G6^2 -> 36
C7: FEBRUARY | D7: 24 | E7: =E6+$M$8*(D6-E6) -> 22 | F7: =D7-E7 -> 2 | G7: =ABS(F7) -> 2 | H7: =G7^2 -> 4 | K7: Initial Forecast | M7: 25
C8: MARCH | D8: 30 | E8: =E7+$M$8*(D7-E7) -> 23 | F8: =D8-E8 -> 7 | G8: =ABS(F8) -> 7 | H8: =G8^2 -> 49 | K8: Smoothing Constant | L8: α | M8: 0.5
C9: APRIL | D9: 32 | E9: =E8+$M$8*(D8-E8) -> 26.5 | F9: =D9-E9 -> 5.5 | G9: =ABS(F9) -> 5.5 | H9: =G9^2 -> 30.25
C10: MAY | D10: 29 | E10: =E9+$M$8*(D9-E9) -> 29.25 | F10: =D10-E10 -> -0.25 | G10: =ABS(F10) -> 0.25 | H10: =G10^2 -> 0.0625
C11: JUNE | D11: 33 | E11: =E10+$M$8*(D10-E10) -> 29.125 | F11: =D11-E11 -> 3.875 | G11: =ABS(F11) -> 3.875 | H11: =G11^2 -> 15.015625
C12: JULY | D12: 34 | E12: =E11+$M$8*(D11-E11) -> 31.0625 | F12: =D12-E12 -> 2.9375 | G12: =ABS(F12) -> 2.9375 | H12: =G12^2 -> 8.6289062
C13: AUGUST | D13: 29 | E13: =E12+$M$8*(D12-E12) -> 32.53125 | F13: =D13-E13 -> -3.53125 | G13: =ABS(F13) -> 3.53125 | H13: =G13^2 -> 12.469727
C14: SEPTEMBER | D14: 29 | E14: =E13+$M$8*(D13-E13) -> 30.765625 | F14: =D14-E14 -> -1.765625 | G14: =ABS(F14) -> 1.765625 | H14: =G14^2 -> 3.1174316
C15: OCTOBER | D15: 32 | E15: =E14+$M$8*(D14-E14) -> 29.882812 | F15: =D15-E15 -> 2.1171875 | G15: =ABS(F15) -> 2.1171875 | H15: =G15^2 -> 4.4824829
C16: NOVEMBER | D16: 31 | E16: =E15+$M$8*(D15-E15) -> 30.941406 | F16: =D16-E16 -> 0.05859375 | G16: =ABS(F16) -> 0.05859375 | H16: =G16^2 -> 0.0034332275
C17: DECEMBER | D17: 25 | E17: =E16+$M$8*(D16-E16) -> 30.970703 | F17: =D17-E17 -> -5.9707031 | G17: =ABS(F17) -> 5.9707031 | H17: =G17^2 -> 35.649296
B18: 2024 | C18: JANUARY | D18: 25 | E18: =E17+$M$8*(D17-E17) -> 27.985352 | F18: =D18-E18 -> -2.9853516 | G18: =ABS(F18) -> 2.9853516 | H18: =G18^2 -> 8.912324
C19: FEBRUARY | D19: 25 | E19: =E18+$M$8*(D18-E18) -> 26.492676 | F19: =D19-E19 -> -1.4926758 | G19: =ABS(F19) -> 1.4926758 | H19: =G19^2 -> 2.228081
C20: MARCH | D20: 28 | E20: =E19+$M$8*(D19-E19) -> 25.746338 | F20: =D20-E20 -> 2.2536621 | G20: =ABS(F20) -> 2.2536621 | H20: =G20^2 -> 5.0789929
C21: APRIL | D21: 30 | E21: =E20+$M$8*(D20-E20) -> 26.873169 | F21: =D21-E21 -> 3.1268311 | G21: =ABS(F21) -> 3.1268311 | H21: =G21^2 -> 9.7770724
C22: MAY | D22: 30 | E22: =E21+$M$8*(D21-E21) -> 28.436584 | F22: =D22-E22 -> 1.5634155 | G22: =ABS(F22) -> 1.5634155 | H22: =G22^2 -> 2.4442681
C23: JUNE | D23: 32 | E23: =E22+$M$8*(D22-E22) -> 29.218292 | F23: =D23-E23 -> 2.7817078 | G23: =ABS(F23) -> 2.7817078 | H23: =G23^2 -> 7.7378981
C24: JULY | D24: 39 | E24: =E23+$M$8*(D23-E23) -> 30.609146 | F24: =D24-E24 -> 8.3908539 | G24: =ABS(F24) -> 8.3908539 | H24: =G24^2 -> 70.406429
C25: AUGUST | D25: 38 | E25: =E24+$M$8*(D24-E24) -> 34.804573 | F25: =D25-E25 -> 3.1954269 | G25: =ABS(F25) -> 3.1954269 | H25: =G25^2 -> 10.210753
C26: SEPTEMBER | D26: 37 | E26: =E25+$M$8*(D25-E25) -> 36.402287 | F26: =D26-E26 -> 0.59771347 | G26: =ABS(F26) -> 0.59771347 | H26: =G26^2 -> 0.35726139
C27: OCTOBER | D27: 40 | E27: =E26+$M$8*(D26-E26) -> 36.701143 | F27: =D27-E27 -> 3.2988567 | G27: =ABS(F27) -> 3.2988567 | H27: =G27^2 -> 10.882456
C28: NOVEMBER | D28: 40 | E28: =E27+$M$8*(D27-E27) -> 38.350572 | F28: =D28-E28 -> 1.6494284 | G28: =ABS(F28) -> 1.6494284 | H28: =G28^2 -> 2.7206139
C29: DECEMBER | D29: 33 | E29: =E28+$M$8*(D28-E28) -> 39.175286 | F29: =D29-E29 -> -6.1752858 | G29: =ABS(F29) -> 6.1752858 | H29: =G29^2 -> 38.134155
B30: 2025 | C30: JANUARY | D30: 35 | E30: =E29+$M$8*(D29-E29) -> 36.087643 | F30: =D30-E30 -> -1.0876429 | G30: =ABS(F30) -> 1.0876429 | H30: =G30^2 -> 1.1829671
C31: FEBRUARY | D31: 31 | E31: =E30+$M$8*(D30-E30) -> 35.543821 | F31: =D31-E31 -> -4.5438215 | G31: =ABS(F31) -> 4.5438215 | H31: =G31^2 -> 20.646313
C32: MARCH | D32: 33 | E32: =E31+$M$8*(D31-E31) -> 33.271911 | F32: =D32-E32 -> -0.27191073 | G32: =ABS(F32) -> 0.27191073 | H32: =G32^2 -> 0.073935443
C33: APRIL | D33: 40 | E33: =E32+$M$8*(D32-E32) -> 33.135955 | F33: =D33-E33 -> 6.8640446 | G33: =ABS(F33) -> 6.8640446 | H33: =G33^2 -> 47.115109
C34: MAY | D34: 38 | E34: =E33+$M$8*(D33-E33) -> 36.567978 | F34: =D34-E34 -> 1.4320223 | G34: =ABS(F34) -> 1.4320223 | H34: =G34^2 -> 2.0506879
C35: JUNE | D35: 36 | E35: =E34+$M$8*(D34-E34) -> 37.283989 | F35: =D35-E35 -> -1.2839888 | G35: =ABS(F35) -> 1.2839888 | H35: =G35^2 -> 1.6486273
C36: JULY | D36: 35 | E36: =E35+$M$8*(D35-E35) -> 36.641994 | F36: =D36-E36 -> -1.6419944 | G36: =ABS(F36) -> 1.6419944 | H36: =G36^2 -> 2.6961457
C37: AUGUST | D37: 29 | E37: =E36+$M$8*(D36-E36) -> 35.820997 | F37: =D37-E37 -> -6.8209972 | G37: =ABS(F37) -> 6.8209972 | H37: =G37^2 -> 46.526003
C38: SEPTEMBER | D38: 25 | E38: =E37+$M$8*(D37-E37) -> 32.410499 | F38: =D38-E38 -> -7.4104986 | G38: =ABS(F38) -> 7.4104986 | H38: =G38^2 -> 54.91549
C39: OCTOBER | D39: 30 | E39: =E38+$M$8*(D38-E38) -> 28.705249 | F39: =D39-E39 -> 1.2947507 | G39: =ABS(F39) -> 1.2947507 | H39: =G39^2 -> 1.6763794
C40: NOVEMBER | D40: 33 | E40: =E39+$M$8*(D39-E39) -> 29.352625 | F40: =D40-E40 -> 3.6473753 | G40: =ABS(F40) -> 3.6473753 | H40: =G40^2 -> 13.303347
C41: DECEMBER | D41: 40 | E41: =E40+$M$8*(D40-E40) -> 31.176312 | F41: =D41-E41 -> 8.8236877 | G41: =ABS(F41) -> 8.8236877 | H41: =G41^2 -> 77.857464
...

Sheet Linear Regression
B2: Linear Regression: Plotting a straight line through the actual demand curve
B4: YEAR | C4: MONTH | D4: ACTUAL DEMAND | E4: REGRESSION
E5: FORECAST | F5: ERROR | G5: ABSOLUTE ERROR | H5: ERROR2
A6: 1 | B6: 2023 | C6: JANUARY | D6: 19 | E6: =(M$8*A6)+M$7 -> 27.765766 | F6: =D6-E6 -> -8.7657658 | G6: =ABS(F6) -> 8.7657658 | H6: =G6^2 -> 76.838649
A7: 2 | C7: FEBRUARY | D7: 24 | E7: =(M$8*A7)+M$7 -> 28.00296 | F7: =D7-E7 -> -4.0029601 | G7: =ABS(F7) -> 4.0029601 | H7: =G7^2 -> 16.02369 | K7: Demand Intercept | L7: c | M7: =INTERCEPT(D6:D41,A6:A41) -> 27.528571 | N7: = INTERCEPT(demand values,time series)
A8: 3 | C8: MARCH | D8: 30 | E8: =(M$8*A8)+M$7 -> 28.240154 | F8: =D8-E8 -> 1.7598456 | G8: =ABS(F8) -> 1.7598456 | H8: =G8^2 -> 3.0970564 | K8: Slope | L8: m | M8: =SLOPE(D6:D41,A6:A41) -> 0.23719434 | N8: = SLOPE(demand values,time series)
A9: 4 | C9: APRIL | D9: 32 | E9: =(M$8*A9)+M$7 -> 28.477349 | F9: =D9-E9 -> 3.5226512 | G9: =ABS(F9) -> 3.5226512 | H9: =G9^2 -> 12.409072
A10: 5 | C10: MAY | D10: 29 | E10: =(M$8*A10)+M$7 -> 28.714543 | F10: =D10-E10 -> 0.28545689 | G10: =ABS(F10) -> 0.28545689 | H10: =G10^2 -> 0.081485633
A11: 6 | C11: JUNE | D11: 33 | E11: =(M$8*A11)+M$7 -> 28.951737 | F11: =D11-E11 -> 4.0482625 | G11: =ABS(F11) -> 4.0482625 | H11: =G11^2 -> 16.38843
A12: 7 | C12: JULY | D12: 34 | E12: =(M$8*A12)+M$7 -> 29.188932 | F12: =D12-E12 -> 4.8110682 | G12: =ABS(F12) -> 4.8110682 | H12: =G12^2 -> 23.146377
A13: 8 | C13: AUGUST | D13: 29 | E13: =(M$8*A13)+M$7 -> 29.426126 | F13: =D13-E13 -> -0.42612613 | G13: =ABS(F13) -> 0.42612613 | H13: =G13^2 -> 0.18158348
A14: 9 | C14: SEPTEMBER | D14: 29 | E14: =(M$8*A14)+M$7 -> 29.66332 | F14: =D14-E14 -> -0.66332046 | G14: =ABS(F14) -> 0.66332046 | H14: =G14^2 -> 0.43999404
A15: 10 | C15: OCTOBER | D15: 32 | E15: =(M$8*A15)+M$7 -> 29.900515 | F15: =D15-E15 -> 2.0994852 | G15: =ABS(F15) -> 2.0994852 | H15: =G15^2 -> 4.4078381
A16: 11 | C16: NOVEMBER | D16: 31 | E16: =(M$8*A16)+M$7 -> 30.137709 | F16: =D16-E16 -> 0.86229086 | G16: =ABS(F16) -> 0.86229086 | H16: =G16^2 -> 0.74354553
A17: 12 | C17: DECEMBER | D17: 25 | E17: =(M$8*A17)+M$7 -> 30.374903 | F17: =D17-E17 -> -5.3749035 | G17: =ABS(F17) -> 5.3749035 | H17: =G17^2 -> 28.889587
A18: 13 | B18: 2024 | C18: JANUARY | D18: 25 | E18: =(M$8*A18)+M$7 -> 30.612098 | F18: =D18-E18 -> -5.6120978 | G18: =ABS(F18) -> 5.6120978 | H18: =G18^2 -> 31.495642
A19: 14 | C19: FEBRUARY | D19: 25 | E19: =(M$8*A19)+M$7 -> 30.849292 | F19: =D19-E19 -> -5.8492921 | G19: =ABS(F19) -> 5.8492921 | H19: =G19^2 -> 34.214219
A20: 15 | C20: MARCH | D20: 28 | E20: =(M$8*A20)+M$7 -> 31.086486 | F20: =D20-E20 -> -3.0864865 | G20: =ABS(F20) -> 3.0864865 | H20: =G20^2 -> 9.5263988
A21: 16 | C21: APRIL | D21: 30 | E21: =(M$8*A21)+M$7 -> 31.323681 | F21: =D21-E21 -> -1.3236808 | G21: =ABS(F21) -> 1.3236808 | H21: =G21^2 -> 1.7521309
A22: 17 | C22: MAY | D22: 30 | E22: =(M$8*A22)+M$7 -> 31.560875 | F22: =D22-E22 -> -1.5608752 | G22: =ABS(F22) -> 1.5608752 | H22: =G22^2 -> 2.4363313
A23: 18 | C23: JUNE | D23: 32 | E23: =(M$8*A23)+M$7 -> 31.798069 | F23: =D23-E23 -> 0.2019305 | G23: =ABS(F23) -> 0.2019305 | H23: =G23^2 -> 0.040775928
A24: 19 | C24: JULY | D24: 39 | E24: =(M$8*A24)+M$7 -> 32.035264 | F24: =D24-E24 -> 6.9647362 | G24: =ABS(F24) -> 6.9647362 | H24: =G24^2 -> 48.50755
A25: 20 | C25: AUGUST | D25: 38 | E25: =(M$8*A25)+M$7 -> 32.272458 | F25: =D25-E25 -> 5.7275418 | G25: =ABS(F25) -> 5.7275418 | H25: =G25^2 -> 32.804735
A26: 21 | C26: SEPTEMBER | D26: 37 | E26: =(M$8*A26)+M$7 -> 32.509653 | F26: =D26-E26 -> 4.4903475 | G26: =ABS(F26) -> 4.4903475 | H26: =G26^2 -> 20.163221
A27: 22 | C27: OCTOBER | D27: 40 | E27: =(M$8*A27)+M$7 -> 32.746847 | F27: =D27-E27 -> 7.2531532 | G27: =ABS(F27) -> 7.2531532 | H27: =G27^2 -> 52.608231
A28: 23 | C28: NOVEMBER | D28: 40 | E28: =(M$8*A28)+M$7 -> 32.984041 | F28: =D28-E28 -> 7.0159588 | G28: =ABS(F28) -> 7.0159588 | H28: =G28^2 -> 49.223678
A29: 24 | C29: DECEMBER | D29: 33 | E29: =(M$8*A29)+M$7 -> 33.221236 | F29: =D29-E29 -> -0.22123552 | G29: =ABS(F29) -> 0.22123552 | H29: =G29^2 -> 0.048945156
A30: 25 | B30: 2025 | C30: JANUARY | D30: 35 | E30: =(M$8*A30)+M$7 -> 33.45843 | F30: =D30-E30 -> 1.5415701 | G30: =ABS(F30) -> 1.5415701 | H30: =G30^2 -> 2.3764385
A31: 26 | C31: FEBRUARY | D31: 31 | E31: =(M$8*A31)+M$7 -> 33.695624 | F31: =D31-E31 -> -2.6956242 | G31: =ABS(F31) -> 2.6956242 | H31: =G31^2 -> 7.2663898
A32: 27 | C32: MARCH | D32: 33 | E32: =(M$8*A32)+M$7 -> 33.932819 | F32: =D32-E32 -> -0.93281853 | G32: =ABS(F32) -> 0.93281853 | H32: =G32^2 -> 0.87015042
A33: 28 | C33: APRIL | D33: 40 | E33: =(M$8*A33)+M$7 -> 34.170013 | F33: =D33-E33 -> 5.8299871 | G33: =ABS(F33) -> 5.8299871 | H33: =G33^2 -> 33.98875
A34: 29 | C34: MAY | D34: 38 | E34: =(M$8*A34)+M$7 -> 34.407207 | F34: =D34-E34 -> 3.5927928 | G34: =ABS(F34) -> 3.5927928 | H34: =G34^2 -> 12.90816
A35: 30 | C35: JUNE | D35: 36 | E35: =(M$8*A35)+M$7 -> 34.644402 | F35: =D35-E35 -> 1.3555985 | G35: =ABS(F35) -> 1.3555985 | H35: =G35^2 -> 1.8376472
A36: 31 | C36: JULY | D36: 35 | E36: =(M$8*A36)+M$7 -> 34.881596 | F36: =D36-E36 -> 0.11840412 | G36: =ABS(F36) -> 0.11840412 | H36: =G36^2 -> 0.014019535
A37: 32 | C37: AUGUST | D37: 29 | E37: =(M$8*A37)+M$7 -> 35.11879 | F37: =D37-E37 -> -6.1187902 | G37: =ABS(F37) -> 6.1187902 | H37: =G37^2 -> 37.439594
A38: 33 | C38: SEPTEMBER | D38: 25 | E38: =(M$8*A38)+M$7 -> 35.355985 | F38: =D38-E38 -> -10.355985 | G38: =ABS(F38) -> 10.355985 | H38: =G38^2 -> 107.24642
A39: 34 | C39: OCTOBER | D39: 30 | E39: =(M$8*A39)+M$7 -> 35.593179 | F39: =D39-E39 -> -5.5931789 | G39: =ABS(F39) -> 5.5931789 | H39: =G39^2 -> 31.28365
A40: 35 | C40: NOVEMBER | D40: 33 | E40: =(M$8*A40)+M$7 -> 35.830373 | F40: =D40-E40 -> -2.8303732 | G40: =ABS(F40) -> 2.8303732 | H40: =G40^2 -> 8.0110126
A41: 36 | C41: DECEMBER | D41: 40 | E41: =(M$8*A41)+M$7 -> 36.067568 | F41: =D41-E41 -> 3.9324324 | G41: =ABS(F41) -> 3.9324324 | H41: =G41^2 -> 15.464025
G42: =AVERAGE(G10:G41) -> 3.5242439 | H42: =AVERAGE(H10:H41) -> 19.243967
...

Sheet Comparision
B2: Comparision of MAD and MSE
B3: Compare from January 2024 to December 2025.
B4: TIME SERIES FORECASTING METHOD | C4: MEAN ABSOLUTE DEVIATION | D4: MEAN SQUARED ERROR
B6: Naïve | C6: =AVERAGE(Naïve!G18:G41) -> 2.9583333 | D6: =AVERAGE(Naïve!H18:H41) -> 14.291667
B7: Naïve with Trend | C7: =AVERAGE('Naïve with Trend'!G18:G41) -> 4.125 | D7: =AVERAGE('Naïve with Trend'!H18:H41) -> 25.291667
B8: Naïve with Seasonality | C8: =AVERAGE('Naïve with Seasonality'!G18:G41) -> 6.3333333 | D8: =AVERAGE('Naïve with Seasonality'!H18:H41) -> 50.25
B9: Moving Average | C9: =AVERAGE('Moving Average'!G18:G41) -> 3.9583333 | D9: =AVERAGE('Moving Average'!H18:H41) -> 23.171296
B10: Exponential Smoothing | C10: =AVERAGE('Exponential Smoothing'!G18:G41) -> 3.443081 | D10: =AVERAGE('Exponential Smoothing'!H18:H41) -> 18.274282
B11: Linear Regression | C11: =AVERAGE('Linear Regression'!G18:G41) -> 3.9252038 | D11: =AVERAGE('Linear Regression'!H18:H41) -> 22.563671

Sheet 2026 & 2027 Forecast
B2: Apply the most suitable forecasting method you have selected to predict demand for 2026 and 2027. Calculate the control limits for 95% confidence level based on past data from 2023 to 2025. Find and plot errors for all 5 years and check if they fall within the control limits. Interpret your graphic result, and explain your findings.
B3: Demand Prediction for 2026 and 2027
B4: Use RMSE for calculating the control limits. Value of z-Score for 95% confidence level is 1.96 (Two-tailed)
B5: YEAR | C5: MONTH | D5: FORECAST | E5: ACTUAL DEMAND | F5: ERROR | G5: ABSOLUTE ERROR | H5: ERROR2 | I5: UCL | J5: LCL | K5: squared deviation from the mean error | L5: UCL | M5: LCL
A6: Past Data | B6: 2023 | C6: JANUARY | E6: 19 | P6: Assume mean error as 0
C7: FEBRUARY | D7: =E6 -> 19 | E7: 24 | F7: =E7-D7 -> 5 | G7: =ABS(F7) -> 5 | H7: =G7^2 -> 25 | I7: =R$10 -> 7.445052 | J7: =R$11 -> -7.445052 | K7: =(F7-$F$66)^2 -> 19.36 | L7: =$R$44 -> 7.9515865 | M7: =$R$45 -> -6.7515865 | P7: Z-Score | Q7: z | R7: 1.96 | S7: = ABS(NORM.S.INV(0.025)) for 95% confidence level
C8: MARCH | D8: =E7 -> 24 | E8: 30 | F8: =E8-D8 -> 6 | G8: =ABS(F8) -> 6 | H8: =G8^2 -> 36 | I8: =R$10 -> 7.445052 | J8: =R$11 -> -7.445052 | K8: =(F8-$F$66)^2 -> 29.16 | L8: =$R$44 -> 7.9515865 | M8: =$R$45 -> -6.7515865 | P8: Mean Squared Error | Q8: MSE | R8: =AVERAGE(H7:H41) -> 14.428571 | S8: Calculated for past data from period 2023 to 2025
C9: APRIL | D9: =E8 -> 30 | E9: 32 | F9: =E9-D9 -> 2 | G9: =ABS(F9) -> 2 | H9: =G9^2 -> 4 | I9: =R$10 -> 7.445052 | J9: =R$11 -> -7.445052 | K9: =(F9-$F$66)^2 -> 1.96 | L9: =$R$44 -> 7.9515865 | M9: =$R$45 -> -6.7515865 | P9: Root Mean Squared Error | Q9: RMSE | R9: =SQRT(R8) -> 3.7984959 | S9: = sqrt(MSE)
C10: MAY | D10: =E9 -> 32 | E10: 29 | F10: =E10-D10 -> -3 | G10: =ABS(F10) -> 3 | H10: =G10^2 -> 9 | I10: =R$10 -> 7.445052 | J10: =R$11 -> -7.445052 | K10: =(F10-$F$66)^2 -> 12.96 | L10: =$R$44 -> 7.9515865 | M10: =$R$45 -> -6.7515865 | P10: Upper Control Limit | Q10: UCL | R10: =R7*R9 -> 7.445052 | S10: = z*RMSE+mean
C11: JUNE | D11: =E10 -> 29 | E11: 33 | F11: =E11-D11 -> 4 | G11: =ABS(F11) -> 4 | H11: =G11^2 -> 16 | I11: =R$10 -> 7.445052 | J11: =R$11 -> -7.445052 | K11: =(F11-$F$66)^2 -> 11.56 | L11: =$R$44 -> 7.9515865 | M11: =$R$45 -> -6.7515865 | P11: Lower Control Limit | Q11: LCL | R11: =-R7*R9 -> -7.445052 | S11: = - z*RMSE+mean
C12: JULY | D12: =E11 -> 33 | E12: 34 | F12: =E12-D12 -> 1 | G12: =ABS(F12) -> 1 | H12: =G12^2 -> 1 | I12: =R$10 -> 7.445052 | J12: =R$11 -> -7.445052 | K12: =(F12-$F$66)^2 -> 0.16 | L12: =$R$44 -> 7.9515865 | M12: =$R$45 -> -6.7515865
C13: AUGUST | D13: =E12 -> 34 | E13: 29 | F13: =E13-D13 -> -5 | G13: =ABS(F13) -> 5 | H13: =G13^2 -> 25 | I13: =R$10 -> 7.445052 | J13: =R$11 -> -7.445052 | K13: =(F13-$F$66)^2 -> 31.36 | L13: =$R$44 -> 7.9515865 | M13: =$R$45 -> -6.7515865
C14: SEPTEMBER | D14: =E13 -> 29 | E14: 29 | F14: =E14-D14 -> 0 | G14: =ABS(F14) -> 0 | H14: =G14^2 -> 0 | I14: =R$10 -> 7.445052 | J14: =R$11 -> -7.445052 | K14: =(F14-$F$66)^2 -> 0.36 | L14: =$R$44 -> 7.9515865 | M14: =$R$45 -> -6.7515865
C15: OCTOBER | D15: =E14 -> 29 | E15: 32 | F15: =E15-D15 -> 3 | G15: =ABS(F15) -> 3 | H15: =G15^2 -> 9 | I15: =R$10 -> 7.445052 | J15: =R$11 -> -7.445052 | K15: =(F15-$F$66)^2 -> 5.76 | L15: =$R$44 -> 7.9515865 | M15: =$R$45 -> -6.7515865
C16: NOVEMBER | D16: =E15 -> 32 | E16: 31 | F16: =E16-D16 -> -1 | G16: =ABS(F16) -> 1 | H16: =G16^2 -> 1 | I16: =R$10 -> 7.445052 | J16: =R$11 -> -7.445052 | K16: =(F16-$F$66)^2 -> 2.56 | L16: =$R$44 -> 7.9515865 | M16: =$R$45 -> -6.7515865
C17: DECEMBER | D17: =E16 -> 31 | E17: 25 | F17: =E17-D17 -> -6 | G17: =ABS(F17) -> 6 | H17: =G17^2 -> 36 | I17: =R$10 -> 7.445052 | J17: =R$11 -> -7.445052 | K17: =(F17-$F$66)^2 -> 43.56 | L17: =$R$44 -> 7.9515865 | M17: =$R$45 -> -6.7515865
B18: 2024 | C18: JANUARY | D18: =E17 -> 25 | E18: 25 | F18: =E18-D18 -> 0 | G18: =ABS(F18) -> 0 | H18: =G18^2 -> 0 | I18: =R$10 -> 7.445052 | J18: =R$11 -> -7.445052 | K18: =(F18-$F$66)^2 -> 0.36 | L18: =$R$44 -> 7.9515865 | M18: =$R$45 -> -6.7515865
C19: FEBRUARY | D19: =E18 -> 25 | E19: 25 | F19: =E19-D19 -> 0 | G19: =ABS(F19) -> 0 | H19: =G19^2 -> 0 | I19: =R$10 -> 7.445052 | J19: =R$11 -> -7.445052 | K19: =(F19-$F$66)^2 -> 0.36 | L19: =$R$44 -> 7.9515865 | M19: =$R$45 -> -6.7515865
C20: MARCH | D20: =E19 -> 25 | E20: 28 | F20: =E20-D20 -> 3 | G20: =ABS(F20) -> 3 | H20: =G20^2 -> 9 | I20: =R$10 -> 7.445052 | J20: =R$11 -> -7.445052 | K20: =(F20-$F$66)^2 -> 5.76 | L20: =$R$44 -> 7.9515865 | M20: =$R$45 -> -6.7515865
C21: APRIL | D21: =E20 -> 28 | E21: 30 | F21: =E21-D21 -> 2 | G21: =ABS(F21) -> 2 | H21: =G21^2 -> 4 | I21: =R$10 -> 7.445052 | J21: =R$11 -> -7.445052 | K21: =(F21-$F$66)^2 -> 1.96 | L21: =$R$44 -> 7.9515865 | M21: =$R$45 -> -6.7515865
C22: MAY | D22: =E21 -> 30 | E22: 30 | F22: =E22-D22 -> 0 | G22: =ABS(F22) -> 0 | H22: =G22^2 -> 0 | I22: =R$10 -> 7.445052 | J22: =R$11 -> -7.445052 | K22: =(F22-$F$66)^2 -> 0.36 | L22: =$R$44 -> 7.9515865 | M22: =$R$45 -> -6.7515865
C23: JUNE | D23: =E22 -> 30 | E23: 32 | F23: =E23-D23 -> 2 | G23: =ABS(F23) -> 2 | H23: =G23^2 -> 4 | I23: =R$10 -> 7.445052 | J23: =R$11 -> -7.445052 | K23: =(F23-$F$66)^2 -> 1.96 | L23: =$R$44 -> 7.9515865 | M23: =$R$45 -> -6.7515865
C24: JULY | D24: =E23 -> 32 | E24: 39 | F24: =E24-D24 -> 7 | G24: =ABS(F24) -> 7 | H24: =G24^2 -> 49 | I24: =R$10 -> 7.445052 | J24: =R$11 -> -7.445052 | K24: =(F24-$F$66)^2 -> 40.96 | L24: =$R$44 -> 7.9515865 | M24: =$R$45 -> -6.7515865
C25: AUGUST | D25: =E24 -> 39 | E25: 38 | F25: =E25-D25 -> -1 | G25: =ABS(F25) -> 1 | H25: =G25^2 -> 1 | I25: =R$10 -> 7.445052 | J25: =R$11 -> -7.445052 | K25: =(F25-$F$66)^2 -> 2.56 | L25: =$R$44 -> 7.9515865 | M25: =$R$45 -> -6.7515865
C26: SEPTEMBER | D26: =E25 -> 38 | E26: 37 | F26: =E26-D26 -> -1 | G26: =ABS(F26) -> 1 | H26: =G26^2 -> 1 | I26: =R$10 -> 7.445052 | J26: =R$11 -> -7.445052 | K26: =(F26-$F$66)^2 -> 2.56 | L26: =$R$44 -> 7.9515865 | M26: =$R$45 -> -6.7515865
C27: OCTOBER | D27: =E26 -> 37 | E27: 40 | F27: =E27-D27 -> 3 | G27: =ABS(F27) -> 3 | H27: =G27^2 -> 9 | I27: =R$10 -> 7.445052 | J27: =R$11 -> -7.445052 | K27: =(F27-$F$66)^2 -> 5.76 | L27: =$R$44 -> 7.9515865 | M27: =$R$45 -> -6.7515865
C28: NOVEMBER | D28: =E27 -> 40 | E28: 40 | F28: =E28-D28 -> 0 | G28: =ABS(F28) -> 0 | H28: =G28^2 -> 0 | I28: =R$10 -> 7.445052 | J28: =R$11 -> -7.445052 | K28: =(F28-$F$66)^2 -> 0.36 | L28: =$R$44 -> 7.9515865 | M28: =$R$45 -> -6.7515865
C29: DECEMBER | D29: =E28 -> 40 | E29: 33 | F29: =E29-D29 -> -7 | G29: =ABS(F29) -> 7 | H29: =G29^2 -> 49 | I29: =R$10 -> 7.445052 | J29: =R$11 -> -7.445052 | K29: =(F29-$F$66)^2 -> 57.76 | L29: =$R$44 -> 7.9515865 | M29: =$R$45 -> -6.7515865
B30: 2025 | C30: JANUARY | D30: =E29 -> 33 | E30: 35 | F30: =E30-D30 -> 2 | G30: =ABS(F30) -> 2 | H30: =G30^2 -> 4 | I30: =R$10 -> 7.445052 | J30: =R$11 -> -7.445052 | K30: =(F30-$F$66)^2 -> 1.96 | L30: =$R$44 -> 7.9515865 | M30: =$R$45 -> -6.7515865
C31: FEBRUARY | D31: =E30 -> 35 | E31: 31 | F31: =E31-D31 -> -4 | G31: =ABS(F31) -> 4 | H31: =G31^2 -> 16 | I31: =R$10 -> 7.445052 | J31: =R$11 -> -7.445052 | K31: =(F31-$F$66)^2 -> 21.16 | L31: =$R$44 -> 7.9515865 | M31: =$R$45 -> -6.7515865
C32: MARCH | D32: =E31 -> 31 | E32: 33 | F32: =E32-D32 -> 2 | G32: =ABS(F32) -> 2 | H32: =G32^2 -> 4 | I32: =R$10 -> 7.445052 | J32: =R$11 -> -7.445052 | K32: =(F32-$F$66)^2 -> 1.96 | L32: =$R$44 -> 7.9515865 | M32: =$R$45 -> -6.7515865
C33: APRIL | D33: =E32 -> 33 | E33: 40 | F33: =E33-D33 -> 7 | G33: =ABS(F33) -> 7 | H33: =G33^2 -> 49 | I33: =R$10 -> 7.445052 | J33: =R$11 -> -7.445052 | K33: =(F33-$F$66)^2 -> 40.96 | L33: =$R$44 -> 7.9515865 | M33: =$R$45 -> -6.7515865
C34: MAY | D34: =E33 -> 40 | E34: 38 | F34: =E34-D34 -> -2 | G34: =ABS(F34) -> 2 | H34: =G34^2 -> 4 | I34: =R$10 -> 7.445052 | J34: =R$11 -> -7.445052 | K34: =(F34-$F$66)^2 -> 6.76 | L34: =$R$44 -> 7.9515865 | M34: =$R$45 -> -6.7515865
C35: JUNE | D35: =E34 -> 38 | E35: 36 | F35: =E35-D35 -> -2 | G35: =ABS(F35) -> 2 | H35: =G35^2 -> 4 | I35: =R$10 -> 7.445052 | J35: =R$11 -> -7.445052 | K35: =(F35-$F$66)^2 -> 6.76 | L35: =$R$44 -> 7.9515865 | M35: =$R$45 -> -6.7515865
C36: JULY | D36: =E35 -> 36 | E36: 35 | F36: =E36-D36 -> -1 | G36: =ABS(F36) -> 1 | H36: =G36^2 -> 1 | I36: =R$10 -> 7.445052 | J36: =R$11 -> -7.445052 | K36: =(F36-$F$66)^2 -> 2.56 | L36: =$R$44 -> 7.9515865 | M36: =$R$45 -> -6.7515865
C37: AUGUST | D37: =E36 -> 35 | E37: 29 | F37: =E37-D37 -> -6 | G37: =ABS(F37) -> 6 | H37: =G37^2 -> 36 | I37: =R$10 -> 7.445052 | J37: =R$11 -> -7.445052 | K37: =(F37-$F$66)^2 -> 43.56 | L37: =$R$44 -> 7.9515865 | M37: =$R$45 -> -6.7515865
C38: SEPTEMBER | D38: =E37 -> 29 | E38: 25 | F38: =E38-D38 -> -4 | G38: =ABS(F38) -> 4 | H38: =G38^2 -> 16 | I38: =R$10 -> 7.445052 | J38: =R$11 -> -7.445052 | K38: =(F38-$F$66)^2 -> 21.16 | L38: =$R$44 -> 7.9515865 | M38: =$R$45 -> -6.7515865
C39: OCTOBER | D39: =E38 -> 25 | E39: 30 | F39: =E39-D39 -> 5 | G39: =ABS(F39) -> 5 | H39: =G39^2 -> 25 | I39: =R$10 -> 7.445052 | J39: =R$11 -> -7.445052 | K39: =(F39-$F$66)^2 -> 19.36 | L39: =$R$44 -> 7.9515865 | M39: =$R$45 -> -6.7515865 | P39: Use the sample mean error
C40: NOVEMBER | D40: =E39 -> 30 | E40: 33 | F40: =E40-D40 -> 3 | G40: =ABS(F40) -> 3 | H40: =G40^2 -> 9 | I40: =R$10 -> 7.445052 | J40: =R$11 -> -7.445052 | K40: =(F40-$F$66)^2 -> 5.76 | L40: =$R$44 -> 7.9515865 | M40: =$R$45 -> -6.7515865 | P40: Z-Score | Q40: z | R40: 1.96
C41: DECEMBER | D41: =E40 -> 33 | E41: 40 | F41: =E41-D41 -> 7 | G41: =ABS(F41) -> 7 | H41: =G41^2 -> 49 | I41: =R$10 -> 7.445052 | J41: =R$11 -> -7.445052 | K41: =(F41-$F$66)^2 -> 40.96 | L41: =$R$44 -> 7.9515865 | M41: =$R$45 -> -6.7515865 | P41: Sample mean error | R41: =AVERAGE(F7:F41) -> 0.6
...
